Workbook

Sheet Erklärungen
B1: Erläuterungen zur Korrelationstabelle
B2: Stand 01.02.2025
B4: Tabelle Transformation | D4: Beschreibt den Übergang von DM.01-AV-CH nach DMAV Version 1.0 und umgekehrt.
A5: Nr. | B5: Spalte | C5: Titel | D5: Inhalt
A6: 10 | B6: =IF(A6="","",IF(ISERROR(SUBSTITUTE(ADDRESS(1,A6,4,1),"1","")),"",SUBSTITUTE(ADDRESS(1,A6,4,1),"1",""))) -> J | C6: {=IF(A6="","",IF(ISERROR(INDEX(Transformation!$A$5:$AT$5,A6)),"",INDEX(Transformation!$A$5:$AT$5,A6)))} -> Link | D6: Hyperlink zum entsprechenden Modell oder Dienst im DMAV Version 1.0
A7: 11 | B7: =IF(A7="","",IF(ISERROR(SUBSTITUTE(ADDRESS(1,A7,4,1),"1","")),"",SUBSTITUTE(ADDRESS(1,A7,4,1),"1",""))) -> K | C7: {=IF(A7="","",IF(ISERROR(INDEX(Transformation!$A$5:$AT$5,A7)),"",INDEX(Transformation!$A$5:$AT$5,A7)))} -> Typ | D7: Art des Elements (Domain, Klasse, Wertebereich etc.)
A8: 12 | B8: =IF(A8="","",IF(ISERROR(SUBSTITUTE(ADDRESS(1,A8,4,1),"1","")),"",SUBSTITUTE(ADDRESS(1,A8,4,1),"1",""))) -> L | C8: {=IF(A8="","",IF(ISERROR(INDEX(Transformation!$A$5:$AT$5,A8)),"",INDEX(Transformation!$A$5:$AT$5,A8)))} -> Topic | D8: Thema / Topic
A9: 13 | B9: =IF(A9="","",IF(ISERROR(SUBSTITUTE(ADDRESS(1,A9,4,1),"1","")),"",SUBSTITUTE(ADDRESS(1,A9,4,1),"1",""))) -> M | C9: {=IF(A9="","",IF(ISERROR(INDEX(Transformation!$A$5:$AT$5,A9)),"",INDEX(Transformation!$A$5:$AT$5,A9)))} -> Class | D9: Benennung des Elements (Domain, Klasse, Wertebereichs etc.)
A10: 14 | B10: =IF(A10="","",IF(ISERROR(SUBSTITUTE(ADDRESS(1,A10,4,1),"1","")),"",SUBSTITUTE(ADDRESS(1,A10,4,1),"1",""))) -> N | C10: {=IF(A10="","",IF(ISERROR(INDEX(Transformation!$A$5:$AT$5,A10)),"",INDEX(Transformation!$A$5:$AT$5,A10)))} -> Attribut | D10: Attributname / Attributsbezeichnung
A11: 15 | B11: =IF(A11="","",IF(ISERROR(SUBSTITUTE(ADDRESS(1,A11,4,1),"1","")),"",SUBSTITUTE(ADDRESS(1,A11,4,1),"1",""))) -> O | C11: {=IF(A11="","",IF(ISERROR(INDEX(Transformation!$A$5:$AT$5,A11)),"",INDEX(Transformation!$A$5:$AT$5,A11)))} -> Structure | D11: Hyperlink zur Definition der Struktur des entsprechenden Attributs
A12: 16 | B12: =IF(A12="","",IF(ISERROR(SUBSTITUTE(ADDRESS(1,A12,4,1),"1","")),"",SUBSTITUTE(ADDRESS(1,A12,4,1),"1",""))) -> P | C12: {=IF(A12="","",IF(ISERROR(INDEX(Transformation!$A$5:$AT$5,A12)),"",INDEX(Transformation!$A$5:$AT$5,A12)))} -> Substruct | D12: Hyperlink zur Definition der Unterstruktur der entsprechenden Struktur
A13: 18 | B13: =IF(A13="","",IF(ISERROR(SUBSTITUTE(ADDRESS(1,A13,4,1),"1","")),"",SUBSTITUTE(ADDRESS(1,A13,4,1),"1",""))) -> R | C13: {=IF(A13="","",IF(ISERROR(INDEX(Transformation!$A$5:$AT$5,A13)),"",INDEX(Transformation!$A$5:$AT$5,A13)))} -> Bemerkung | D13: Defaultwert oder Mapping der Werte beim Übergang von DM.01-AV-CH nach DMAV Version 1.0
A14: 20 | B14: =IF(A14="","",IF(ISERROR(SUBSTITUTE(ADDRESS(1,A14,4,1),"1","")),"",SUBSTITUTE(ADDRESS(1,A14,4,1),"1",""))) -> T | C14: {=IF(A14="","",IF(ISERROR(INDEX(Transformation!$A$5:$AT$5,A14)),"",INDEX(Transformation!$A$5:$AT$5,A14)))} -> Bedingung / Voraussetzung in DM.01-AV-CH | D14: Bedingung im DM.01-AV-CH damit das Attribut / der Datensatz ins DMAV Version 1.0 übertragen wird
A15: 21 | B15: =IF(A15="","",IF(ISERROR(SUBSTITUTE(ADDRESS(1,A15,4,1),"1","")),"",SUBSTITUTE(ADDRESS(1,A15,4,1),"1",""))) -> U | C15: {=IF(A15="","",IF(ISERROR(INDEX(Transformation!$A$5:$AT$5,A15)),"",INDEX(Transformation!$A$5:$AT$5,A15)))} -> T | D15: Art der Transformation: K = kopieren V = verschieben
A16: 22 | B16: =IF(A16="","",IF(ISERROR(SUBSTITUTE(ADDRESS(1,A16,4,1),"1","")),"",SUBSTITUTE(ADDRESS(1,A16,4,1),"1",""))) -> V | C16: {=IF(A16="","",IF(ISERROR(INDEX(Transformation!$A$5:$AT$5,A16)),"",INDEX(Transformation!$A$5:$AT$5,A16)))} -> Klasse | D16: In welche Klasse, welches Attribut sind die Daten vom DM.01-AV-CH nach DMAV Version 1.0 zu überführen?
A17: 23 | B17: =IF(A17="","",IF(ISERROR(SUBSTITUTE(ADDRESS(1,A17,4,1),"1","")),"",SUBSTITUTE(ADDRESS(1,A17,4,1),"1",""))) -> W | C17: {=IF(A17="","",IF(ISERROR(INDEX(Transformation!$A$5:$AT$5,A17)),"",INDEX(Transformation!$A$5:$AT$5,A17)))} -> Ergänzung | D17: Wie sind die als MANDATORY bezeichneten Attribute im DMAV Version 1.0 zu ergänzen, sodass das Objekt konsistent im DMAV Version 1.0 abgebildet wird
... A26: 35 | B26: =IF(A26="","",IF(ISERROR(SUBSTITUTE(ADDRESS(1,A26,4,1),"1","")),"",SUBSTITUTE(ADDRESS(1,A26,4,1),"1",""))) -> AI | C26: {=IF(A26="","",IF(ISERROR(INDEX(Transformation!$A$5:$AT$5,A26)),"",INDEX(Transformation!$A$5:$AT$5,A26)))} -> Attribut | D26: Attributname / Attributsbezeichnung
B28: Tabelle DMAV_Doku | D28: Enthält den Objektkatalog aus den Modelldokumentationen.
B29: Spalte | C29: Titel | D29: Inhalt
A30: 1 | B30: =IF(A30="","",IF(ISERROR(SUBSTITUTE(ADDRESS(1,A30,4,1),"1","")),"",SUBSTITUTE(ADDRESS(1,A30,4,1),"1",""))) -> A | C30: {=IF(A30="","",IF(ISERROR(INDEX(DMAV_Doku!$A$5:$AH$5,A30)),"",INDEX(DMAV_Doku!$A$5:$AH$5,A30)))} -> Dok | D30: Kürzel für das Geodatenmodell
A31: 2 | B31: =IF(A31="","",IF(ISERROR(SUBSTITUTE(ADDRESS(1,A31,4,1),"1","")),"",SUBSTITUTE(ADDRESS(1,A31,4,1),"1",""))) -> B | C31: {=IF(A31="","",IF(ISERROR(INDEX(DMAV_Doku!$A$5:$AH$5,A31)),"",INDEX(DMAV_Doku!$A$5:$AH$5,A31)))} -> Nr. | D31: Zeilennummer
A32: 3 | B32: =IF(A32="","",IF(ISERROR(SUBSTITUTE(ADDRESS(1,A32,4,1),"1","")),"",SUBSTITUTE(ADDRESS(1,A32,4,1),"1",""))) -> C | C32: {=IF(A32="","",IF(ISERROR(INDEX(DMAV_Doku!$A$5:$AH$5,A32)),"",INDEX(DMAV_Doku!$A$5:$AH$5,A32)))} -> Typ | D32: Art des Elements (Domain, Klasse, Wertebereich etc.)
A33: 4 | B33: =IF(A33="","",IF(ISERROR(SUBSTITUTE(ADDRESS(1,A33,4,1),"1","")),"",SUBSTITUTE(ADDRESS(1,A33,4,1),"1",""))) -> D | C33: {=IF(A33="","",IF(ISERROR(INDEX(DMAV_Doku!$A$5:$AH$5,A33)),"",INDEX(DMAV_Doku!$A$5:$AH$5,A33)))} -> MAN. | D33: MANDATORY, sind Daten zu diesem Attribut zu erfassen: 0..1 = optional (nicht MANDATORY) 1 = obligatorisch (MANDATORY)
A34: 6 | B34: =IF(A34="","",IF(ISERROR(SUBSTITUTE(ADDRESS(1,A34,4,1),"1","")),"",SUBSTITUTE(ADDRESS(1,A34,4,1),"1",""))) -> F | C34: {=IF(A34="","",IF(ISERROR(INDEX(DMAV_Doku!$A$5:$AH$5,A34)),"",INDEX(DMAV_Doku!$A$5:$AH$5,A34)))} -> Domain | D34: Hyperlink zur Definition des Wertebereichs des entsprechenden Attributs
A35: 7 | B35: =IF(A35="","",IF(ISERROR(SUBSTITUTE(ADDRESS(1,A35,4,1),"1","")),"",SUBSTITUTE(ADDRESS(1,A35,4,1),"1",""))) -> G | C35: {=IF(A35="","",IF(ISERROR(INDEX(DMAV_Doku!$A$5:$AH$5,A35)),"",INDEX(DMAV_Doku!$A$5:$AH$5,A35)))} -> Modell | D35: Hyperlink zum entsprechenden Attribut, Struktur, Wertebereich im DMAV Version 1.0
A36: 12 | B36: =IF(A36="","",IF(ISERROR(SUBSTITUTE(ADDRESS(1,A36,4,1),"1","")),"",SUBSTITUTE(ADDRESS(1,A36,4,1),"1",""))) -> L | C36: {=IF(A36="","",IF(ISERROR(INDEX(DMAV_Doku!$A$5:$AH$5,A36)),"",INDEX(DMAV_Doku!$A$5:$AH$5,A36)))} -> Dokument | D36: Name der deutschen Modelldokumentation, in welcher das Attribut, der Wertebereich beschrieben ist
A37: 13 | B37: =IF(A37="","",IF(ISERROR(SUBSTITUTE(ADDRESS(1,A37,4,1),"1","")),"",SUBSTITUTE(ADDRESS(1,A37,4,1),"1",""))) -> M | C37: {=IF(A37="","",IF(ISERROR(INDEX(DMAV_Doku!$A$5:$AH$5,A37)),"",INDEX(DMAV_Doku!$A$5:$AH$5,A37)))} -> Name | D37: Name der Klasse (deutsch)
A38: 14 | B38: =IF(A38="","",IF(ISERROR(SUBSTITUTE(ADDRESS(1,A38,4,1),"1","")),"",SUBSTITUTE(ADDRESS(1,A38,4,1),"1",""))) -> N | C38: {=IF(A38="","",IF(ISERROR(INDEX(DMAV_Doku!$A$5:$AH$5,A38)),"",INDEX(DMAV_Doku!$A$5:$AH$5,A38)))} -> Attribut | D38: Name des Attributs (deutsch)
A39: 15 | B39: =IF(A39="","",IF(ISERROR(SUBSTITUTE(ADDRESS(1,A39,4,1),"1","")),"",SUBSTITUTE(ADDRESS(1,A39,4,1),"1",""))) -> O | C39: {=IF(A39="","",IF(ISERROR(INDEX(DMAV_Doku!$A$5:$AH$5,A39)),"",INDEX(DMAV_Doku!$A$5:$AH$5,A39)))} -> Wert | D39: Wertebereich des Attributs
A40: 16 | B40: =IF(A40="","",IF(ISERROR(SUBSTITUTE(ADDRESS(1,A40,4,1),"1","")),"",SUBSTITUTE(ADDRESS(1,A40,4,1),"1",""))) -> P | C40: {=IF(A40="","",IF(ISERROR(INDEX(DMAV_Doku!$A$5:$AH$5,A40)),"",INDEX(DMAV_Doku!$A$5:$AH$5,A40)))} -> Default | D40: Defaultwert für das Attribut
A41: 17 | B41: =IF(A41="","",IF(ISERROR(SUBSTITUTE(ADDRESS(1,A41,4,1),"1","")),"",SUBSTITUTE(ADDRESS(1,A41,4,1),"1",""))) -> Q | C41: {=IF(A41="","",IF(ISERROR(INDEX(DMAV_Doku!$A$5:$AH$5,A41)),"",INDEX(DMAV_Doku!$A$5:$AH$5,A41)))} -> Beschreibung | D41: Beschreibung des Attributs gemäss Modelldokumentation (deutsch)
... A56: 34 | B56: =IF(A56="","",IF(ISERROR(SUBSTITUTE(ADDRESS(1,A56,4,1),"1","")),"",SUBSTITUTE(ADDRESS(1,A56,4,1),"1",""))) -> AH | C56: {=IF(A56="","",IF(ISERROR(INDEX(DMAV_Doku!$A$5:$AH$5,A56)),"",INDEX(DMAV_Doku!$A$5:$AH$5,A56)))} -> Commento | D56: Commento all'attributo / requisiti per la modellazione dei dati secondo la documentazione del modello (in italiano)
B58: Tabelle DMAV_Modell | D58: Enthält den Objektkatalog aus der Modellbeschreibung in INTERLIS 2.4.
B59: Spalte | C59: Titel | D59: Inhalt
A60: 1 | B60: =IF(A60="","",IF(ISERROR(SUBSTITUTE(ADDRESS(1,A60,4,1),"1","")),"",SUBSTITUTE(ADDRESS(1,A60,4,1),"1",""))) -> A | C60: {=IF(A60="","",IF(ISERROR(INDEX(DMAV_Modell!$A$5:$BB$5,A60)),"",INDEX(DMAV_Modell!$A$5:$BB$5,A60)))} -> Modell | D60: Kürzel für das Geodatenmodell
A61: 2 | B61: =IF(A61="","",IF(ISERROR(SUBSTITUTE(ADDRESS(1,A61,4,1),"1","")),"",SUBSTITUTE(ADDRESS(1,A61,4,1),"1",""))) -> B | C61: {=IF(A61="","",IF(ISERROR(INDEX(DMAV_Modell!$A$5:$BB$5,A61)),"",INDEX(DMAV_Modell!$A$5:$BB$5,A61)))} -> Nr | D61: Zeilennummer
A62: 4 | B62: =IF(A62="","",IF(ISERROR(SUBSTITUTE(ADDRESS(1,A62,4,1),"1","")),"",SUBSTITUTE(ADDRESS(1,A62,4,1),"1",""))) -> D | C62: {=IF(A62="","",IF(ISERROR(INDEX(DMAV_Modell!$A$5:$BB$5,A62)),"",INDEX(DMAV_Modell!$A$5:$BB$5,A62)))} -> CheckID | D62: Identifikator der Bedingung (Constraint)
A63: 5 | B63: =IF(A63="","",IF(ISERROR(SUBSTITUTE(ADDRESS(1,A63,4,1),"1","")),"",SUBSTITUTE(ADDRESS(1,A63,4,1),"1",""))) -> E | C63: {=IF(A63="","",IF(ISERROR(INDEX(DMAV_Modell!$A$5:$BB$5,A63)),"",INDEX(DMAV_Modell!$A$5:$BB$5,A63)))} -> Domain | D63: Hyperlink zur Definition des Wertebereichs des entsprechenden Attributs
A64: 6 | B64: =IF(A64="","",IF(ISERROR(SUBSTITUTE(ADDRESS(1,A64,4,1),"1","")),"",SUBSTITUTE(ADDRESS(1,A64,4,1),"1",""))) -> F | C64: {=IF(A64="","",IF(ISERROR(INDEX(DMAV_Modell!$A$5:$BB$5,A64)),"",INDEX(DMAV_Modell!$A$5:$BB$5,A64)))} -> Doku | D64: Hyperlink zur entsprechenden Beschreibung in der Modelldokumentation
A65: 11 | B65: =IF(A65="","",IF(ISERROR(SUBSTITUTE(ADDRESS(1,A65,4,1),"1","")),"",SUBSTITUTE(ADDRESS(1,A65,4,1),"1",""))) -> K | C65: {=IF(A65="","",IF(ISERROR(INDEX(DMAV_Modell!$A$5:$BB$5,A65)),"",INDEX(DMAV_Modell!$A$5:$BB$5,A65)))} -> Neu | D65: Datum der Einführung oder der Ergänzung des Elements
...

Sheet Transformation
J1: Modelltransfer (DMAV <> DM.01-AV-CH)
J2: Stand: 01.02.2026
A4: Zeile | B4: {=MID(CELL("adresse",DMAV_Modell!$A$1),FIND("]",CELL("adresse",DMAV_Modell!$A$1))+1,FIND("!",CELL("adresse",DMAV_Modell!$A$1))-FIND("]",CELL("adresse",DMAV_Modell!$A$1))-1)} -> DMAV_Modell | E4: {=MID(CELL("adresse",DMAV_Dienste!$A$1),FIND("]",CELL("adresse",DMAV_Dienste!$A$1))+1,FIND("!",CELL("adresse",DMAV_Dienste!$A$1))-FIND("]",CELL("adresse",DMAV_Dienste!$A$1))-1)} -> DMAV_Dienste | H4: {="'"&MID(CELL("adresse",'DM01-AV-CH'!$A$1),FIND("]",CELL("adresse",'DM01-AV-CH'!$A$1))+1,FIND("!",CELL("adresse",'DM01-AV-CH'!$A$1))-FIND("]",CELL("adresse",'DM01-AV-CH'!$A$1))-1)} -> 'DM01-AV-CH' | K4: DMAV Version 1.0 | T4: Übergang von DM.01-AV-CH nach DMAV Version 1.0 | Y4: Übergang von DMAV Version 1.0 nach DM.01-AV-CH | AG4: DM.01-AV-CH
A5: Nr. | B5: DR1 | C5: DR2 | D5: DR3 | E5: GR1 | F5: GR2 | G5: GR3 | H5: R1 | J5: Link | K5: Typ | L5: Topic | M5: Class | N5: Attribut | O5: Structure | P5: Substruct | R5: Bemerkung | T5: Bedingung / Voraussetzung in DM.01-AV-CH | U5: T | V5: Klasse | W5: Ergänzung | Y5: Bedingung / Voraussetzung in DMAV | Z5: T | AA5: Tabelle | AB5: Ergänzung | AD5: Bemerkungen | AF5: Link | AG5: Topic | AH5: Tabelle | AI5: Attribut
A6: 1 | B6: =IF($A6="","",IF(_xlfn.XLOOKUP($A6,Korrelation!$D$4:$D$1197,Korrelation!E$4:E$1197,"-",0)="-",0,MATCH(_xlfn.XLOOKUP($A6,Korrelation!$D$4:$D$1197,Korrelation!E$4:E$1197,"",0),DMAV_Modell!$G$6:$G$677,0))) -> 1 | C6: =IF($A6="","",IF(_xlfn.XLOOKUP($A6,Korrelation!$D$4:$D$1197,Korrelation!F$4:F$1197,"-",0)="-",0,MATCH(_xlfn.XLOOKUP($A6,Korrelation!$D$4:$D$1197,Korrelation!F$4:F$1197,"",0),DMAV_Modell!$G$6:$G$677,0))) -> 0 | D6: =IF($A6="","",IF(_xlfn.XLOOKUP($A6,Korrelation!$D$4:$D$1197,Korrelation!G$4:G$1197,"-",0)="-",0,MATCH(_xlfn.XLOOKUP($A6,Korrelation!$D$4:$D$1197,Korrelation!G$4:G$1197,"",0),DMAV_Modell!$G$6:$G$677,0))) -> 0 | E6: =IF($A6="","",IF(_xlfn.XLOOKUP($A6,Korrelation!$D$4:$D$1197,Korrelation!H$4:H$1197,"-",0)="-",0,MATCH(_xlfn.XLOOKUP($A6,Korrelation!$D$4:$D$1197,Korrelation!H$4:H$1197,"",0),DMAV_Dienste!$F$6:$F$140,0))) -> 0 | F6: =IF($A6="","",IF(_xlfn.XLOOKUP($A6,Korrelation!$D$4:$D$1197,Korrelation!I$4:I$1197,"-",0)="-",0,MATCH(_xlfn.XLOOKUP($A6,Korrelation!$D$4:$D$1197,Korrelation!I$4:I$1197,"",0),DMAV_Dienste!$F$6:$F$140,0))) -> 0 | G6: =IF($A6="","",IF(_xlfn.XLOOKUP($A6,Korrelation!$D$4:$D$1197,Korrelation!J$4:J$1197,"-",0)="-",0,MATCH(_xlfn.XLOOKUP($A6,Korrelation!$D$4:$D$1197,Korrelation!J$4:J$1197,"",0),DMAV_Dienste!$F$6:$F$140,0))) -> 0 | H6: =IF($A6="","",IF(_xlfn.XLOOKUP($A6,Korrelation!$D$4:$D$1197,Korrelation!K$4:K$1197,"-",0)="-",0,MATCH(_xlfn.XLOOKUP($A6,Korrelation!$D$4:$D$1197,Korrelation!K$4:K$1197,"",0),'DM01-AV-CH'!$A$6:$A$834,0))) -> 0 | J6: {=IF(B6=0,IF(E6=0,"",HYPERLINK("#"&RIGHT(CELL("adresse",OFFSET(DMAV_Dienste!$M$6,E6-1,0)),LEN(CELL("adresse",OFFSET(DMAV_Dienste!$M$6,E6-1,0)))-FIND("]",CELL("adresse",OFFSET(DMAV_Dienste!$M$6,E6-1,0)))),"Dienst")),HYPERLINK("#"&RIGHT(CELL("adresse",OFFSET(DMAV_Modell!$N$6,B6-1,0)),LEN(CELL("adresse",OFFSET(DMAV_Modell!$N$6,B6-1,0)))-FIND("]",CELL("adresse",OFFSET(DMAV_Modell!$N$6,B6-1,0)))),"Modell"))} -> Modell | K6: {=IF($B6=0,IF($E6=0,"",IF(INDEX(DMAV_Dienste!P$6:P$140,$E6)="","",INDEX(DMAV_Dienste!P$6:P$140,$E6))),IF(INDEX(DMAV_Modell!Q$6:Q$838,$B6)="","",INDEX(DMAV_Modell!Q$6:Q$838,$B6)))} -> IMPORTS | L6: {=IF($B6=0,IF($E6=0,"",IF(INDEX(DMAV_Dienste!O$6:O$140,$E6)="","",INDEX(DMAV_Dienste!O$6:O$140,$E6))),IF(INDEX(DMAV_Modell!P$6:P$838,$B6)="","",INDEX(DMAV_Modell!P$6:P$838,$B6)))} | M6: {=IF($B6=0,IF($E6=0,"",IF(INDEX(DMAV_Dienste!Q$6:Q$140,$E6)="","",INDEX(DMAV_Dienste!Q$6:Q$140,$E6))),IF(INDEX(DMAV_Modell!R$6:R$838,$B6)="","",INDEX(DMAV_Modell!R$6:R$838,$B6)))} -> DMAV_Bodenbedeckung_V1_1 | N6: {=IF($B6=0,IF($E6=0,"",IF(INDEX(DMAV_Dienste!T$6:T$140,$E6)="","",INDEX(DMAV_Dienste!T$6:T$140,$E6))),IF(INDEX(DMAV_Modell!U$6:U$838,$B6)="","",INDEX(DMAV_Modell!U$6:U$838,$B6)))} | O6: {=IF(C6=0,IF(F6=0,"",HYPERLINK("#"&RIGHT(CELL("adresse",OFFSET(DMAV_Dienste!$M$6,F6-1,0)),LEN(CELL("adresse",OFFSET(DMAV_Dienste!$M$6,F6-1,0)))-FIND("]",CELL("adresse",OFFSET(DMAV_Dienste!$M$6,F6-1,0)))),"Structure")),HYPERLINK("#"&RIGHT(CELL("adresse",OFFSET(DMAV_Modell!$N$6,C6-1,0)),LEN(CELL("adresse",OFFSET(DMAV_Modell!$N$6,C6-1,0)))-FIND("]",CELL("adresse",OFFSET(DMAV_Modell!$N$6,C6-1,0)))),"Structure"))} | P6: {=IF(D6=0,IF(G6=0,"",HYPERLINK("#"&RIGHT(CELL("adresse",OFFSET(DMAV_Dienste!$M$6,G6-1,0)),LEN(CELL("adresse",OFFSET(DMAV_Dienste!$M$6,G6-1,0)))-FIND("]",CELL("adresse",OFFSET(DMAV_Dienste!$M$6,G6-1,0)))),"Substructure")),HYPERLINK("#"&RIGHT(CELL("adresse",OFFSET(DMAV_Modell!$N$6,D6-1,0)),LEN(CELL("adresse",OFFSET(DMAV_Modell!$N$6,D6-1,0)))-FIND("]",CELL("adresse",OFFSET(DMAV_Modell!$N$6,D6-1,0)))),"Substructure"))} | AF6: {=IF(H6=0,"",HYPERLINK("#"&RIGHT(CELL("adresse",OFFSET('DM01-AV-CH'!$G$6,H6-1,0)),LEN(CELL("adresse",OFFSET('DM01-AV-CH'!$G$6,H6-1,0)))-FIND("]",CELL("adresse",OFFSET('DM01-AV-CH'!$G$6,H6-1,0)))),"Modell"))} | AG6: {=IF($H6=0,"",IF(INDEX('DM01-AV-CH'!G$6:G$834,$H6)="","",INDEX('DM01-AV-CH'!G$6:G$834,$H6)))} | AH6: {=IF($H6=0,"",IF(INDEX('DM01-AV-CH'!H$6:H$834,$H6)="","",INDEX('DM01-AV-CH'!H$6:H$834,$H6)))} | AI6: {=IF($H6=0,"",IF(INDEX('DM01-AV-CH'!I$6:I$834,$H6)="","",INDEX('DM01-AV-CH'!I$6:I$834,$H6)))}
A7: 2 | B7: =IF($A7="","",IF(_xlfn.XLOOKUP($A7,Korrelation!$D$4:$D$1197,Korrelation!E$4:E$1197,"-",0)="-",0,MATCH(_xlfn.XLOOKUP($A7,Korrelation!$D$4:$D$1197,Korrelation!E$4:E$1197,"",0),DMAV_Modell!$G$6:$G$677,0))) -> 2 | C7: =IF($A7="","",IF(_xlfn.XLOOKUP($A7,Korrelation!$D$4:$D$1197,Korrelation!F$4:F$1197,"-",0)="-",0,MATCH(_xlfn.XLOOKUP($A7,Korrelation!$D$4:$D$1197,Korrelation!F$4:F$1197,"",0),DMAV_Modell!$G$6:$G$677,0))) -> 0 | D7: =IF($A7="","",IF(_xlfn.XLOOKUP($A7,Korrelation!$D$4:$D$1197,Korrelation!G$4:G$1197,"-",0)="-",0,MATCH(_xlfn.XLOOKUP($A7,Korrelation!$D$4:$D$1197,Korrelation!G$4:G$1197,"",0),DMAV_Modell!$G$6:$G$677,0))) -> 0 | E7: =IF($A7="","",IF(_xlfn.XLOOKUP($A7,Korrelation!$D$4:$D$1197,Korrelation!H$4:H$1197,"-",0)="-",0,MATCH(_xlfn.XLOOKUP($A7,Korrelation!$D$4:$D$1197,Korrelation!H$4:H$1197,"",0),DMAV_Dienste!$F$6:$F$140,0))) -> 0 | F7: =IF($A7="","",IF(_xlfn.XLOOKUP($A7,Korrelation!$D$4:$D$1197,Korrelation!I$4:I$1197,"-",0)="-",0,MATCH(_xlfn.XLOOKUP($A7,Korrelation!$D$4:$D$1197,Korrelation!I$4:I$1197,"",0),DMAV_Dienste!$F$6:$F$140,0))) -> 0 | G7: =IF($A7="","",IF(_xlfn.XLOOKUP($A7,Korrelation!$D$4:$D$1197,Korrelation!J$4:J$1197,"-",0)="-",0,MATCH(_xlfn.XLOOKUP($A7,Korrelation!$D$4:$D$1197,Korrelation!J$4:J$1197,"",0),DMAV_Dienste!$F$6:$F$140,0))) -> 0 | H7: =IF($A7="","",IF(_xlfn.XLOOKUP($A7,Korrelation!$D$4:$D$1197,Korrelation!K$4:K$1197,"-",0)="-",0,MATCH(_xlfn.XLOOKUP($A7,Korrelation!$D$4:$D$1197,Korrelation!K$4:K$1197,"",0),'DM01-AV-CH'!$A$6:$A$834,0))) -> 0 | J7: {=IF(B7=0,IF(E7=0,"",HYPERLINK("#"&RIGHT(CELL("adresse",OFFSET(DMAV_Dienste!$M$6,E7-1,0)),LEN(CELL("adresse",OFFSET(DMAV_Dienste!$M$6,E7-1,0)))-FIND("]",CELL("adresse",OFFSET(DMAV_Dienste!$M$6,E7-1,0)))),"Dienst")),HYPERLINK("#"&RIGHT(CELL("adresse",OFFSET(DMAV_Modell!$N$6,B7-1,0)),LEN(CELL("adresse",OFFSET(DMAV_Modell!$N$6,B7-1,0)))-FIND("]",CELL("adresse",OFFSET(DMAV_Modell!$N$6,B7-1,0)))),"Modell"))} -> Modell | K7: {=IF($B7=0,IF($E7=0,"",IF(INDEX(DMAV_Dienste!P$6:P$140,$E7)="","",INDEX(DMAV_Dienste!P$6:P$140,$E7))),IF(INDEX(DMAV_Modell!Q$6:Q$838,$B7)="","",INDEX(DMAV_Modell!Q$6:Q$838,$B7)))} -> IMPORTS | L7: {=IF($B7=0,IF($E7=0,"",IF(INDEX(DMAV_Dienste!O$6:O$140,$E7)="","",INDEX(DMAV_Dienste!O$6:O$140,$E7))),IF(INDEX(DMAV_Modell!P$6:P$838,$B7)="","",INDEX(DMAV_Modell!P$6:P$838,$B7)))} | M7: {=IF($B7=0,IF($E7=0,"",IF(INDEX(DMAV_Dienste!Q$6:Q$140,$E7)="","",INDEX(DMAV_Dienste!Q$6:Q$140,$E7))),IF(INDEX(DMAV_Modell!R$6:R$838,$B7)="","",INDEX(DMAV_Modell!R$6:R$838,$B7)))} -> DMAV_DauerndeBodenverschiebungen_V1_1 | N7: {=IF($B7=0,IF($E7=0,"",IF(INDEX(DMAV_Dienste!T$6:T$140,$E7)="","",INDEX(DMAV_Dienste!T$6:T$140,$E7))),IF(INDEX(DMAV_Modell!U$6:U$838,$B7)="","",INDEX(DMAV_Modell!U$6:U$838,$B7)))} | O7: {=IF(C7=0,IF(F7=0,"",HYPERLINK("#"&RIGHT(CELL("adresse",OFFSET(DMAV_Dienste!$M$6,F7-1,0)),LEN(CELL("adresse",OFFSET(DMAV_Dienste!$M$6,F7-1,0)))-FIND("]",CELL("adresse",OFFSET(DMAV_Dienste!$M$6,F7-1,0)))),"Structure")),HYPERLINK("#"&RIGHT(CELL("adresse",OFFSET(DMAV_Modell!$N$6,C7-1,0)),LEN(CELL("adresse",OFFSET(DMAV_Modell!$N$6,C7-1,0)))-FIND("]",CELL("adresse",OFFSET(DMAV_Modell!$N$6,C7-1,0)))),"Structure"))} | P7: {=IF(D7=0,IF(G7=0,"",HYPERLINK("#"&RIGHT(CELL("adresse",OFFSET(DMAV_Dienste!$M$6,G7-1,0)),LEN(CELL("adresse",OFFSET(DMAV_Dienste!$M$6,G7-1,0)))-FIND("]",CELL("adresse",OFFSET(DMAV_Dienste!$M$6,G7-1,0)))),"Substructure")),HYPERLINK("#"&RIGHT(CELL("adresse",OFFSET(DMAV_Modell!$N$6,D7-1,0)),LEN(CELL("adresse",OFFSET(DMAV_Modell!$N$6,D7-1,0)))-FIND("]",CELL("adresse",OFFSET(DMAV_Modell!$N$6,D7-1,0)))),"Substructure"))} | AF7: {=IF(H7=0,"",HYPERLINK("#"&RIGHT(CELL("adresse",OFFSET('DM01-AV-CH'!$G$6,H7-1,0)),LEN(CELL("adresse",OFFSET('DM01-AV-CH'!$G$6,H7-1,0)))-FIND("]",CELL("adresse",OFFSET('DM01-AV-CH'!$G$6,H7-1,0)))),"Modell"))} | AG7: {=IF($H7=0,"",IF(INDEX('DM01-AV-CH'!G$6:G$834,$H7)="","",INDEX('DM01-AV-CH'!G$6:G$834,$H7)))} | AH7: {=IF($H7=0,"",IF(INDEX('DM01-AV-CH'!H$6:H$834,$H7)="","",INDEX('DM01-AV-CH'!H$6:H$834,$H7)))} | AI7: {=IF($H7=0,"",IF(INDEX('DM01-AV-CH'!I$6:I$834,$H7)="","",INDEX('DM01-AV-CH'!I$6:I$834,$H7)))}
A8: 3 | B8: =IF($A8="","",IF(_xlfn.XLOOKUP($A8,Korrelation!$D$4:$D$1197,Korrelation!E$4:E$1197,"-",0)="-",0,MATCH(_xlfn.XLOOKUP($A8,Korrelation!$D$4:$D$1197,Korrelation!E$4:E$1197,"",0),DMAV_Modell!$G$6:$G$677,0))) -> 3 | C8: =IF($A8="","",IF(_xlfn.XLOOKUP($A8,Korrelation!$D$4:$D$1197,Korrelation!F$4:F$1197,"-",0)="-",0,MATCH(_xlfn.XLOOKUP($A8,Korrelation!$D$4:$D$1197,Korrelation!F$4:F$1197,"",0),DMAV_Modell!$G$6:$G$677,0))) -> 0 | D8: =IF($A8="","",IF(_xlfn.XLOOKUP($A8,Korrelation!$D$4:$D$1197,Korrelation!G$4:G$1197,"-",0)="-",0,MATCH(_xlfn.XLOOKUP($A8,Korrelation!$D$4:$D$1197,Korrelation!G$4:G$1197,"",0),DMAV_Modell!$G$6:$G$677,0))) -> 0 | E8: =IF($A8="","",IF(_xlfn.XLOOKUP($A8,Korrelation!$D$4:$D$1197,Korrelation!H$4:H$1197,"-",0)="-",0,MATCH(_xlfn.XLOOKUP($A8,Korrelation!$D$4:$D$1197,Korrelation!H$4:H$1197,"",0),DMAV_Dienste!$F$6:$F$140,0))) -> 0 | F8: =IF($A8="","",IF(_xlfn.XLOOKUP($A8,Korrelation!$D$4:$D$1197,Korrelation!I$4:I$1197,"-",0)="-",0,MATCH(_xlfn.XLOOKUP($A8,Korrelation!$D$4:$D$1197,Korrelation!I$4:I$1197,"",0),DMAV_Dienste!$F$6:$F$140,0))) -> 0 | G8: =IF($A8="","",IF(_xlfn.XLOOKUP($A8,Korrelation!$D$4:$D$1197,Korrelation!J$4:J$1197,"-",0)="-",0,MATCH(_xlfn.XLOOKUP($A8,Korrelation!$D$4:$D$1197,Korrelation!J$4:J$1197,"",0),DMAV_Dienste!$F$6:$F$140,0))) -> 0 | H8: =IF($A8="","",IF(_xlfn.XLOOKUP($A8,Korrelation!$D$4:$D$1197,Korrelation!K$4:K$1197,"-",0)="-",0,MATCH(_xlfn.XLOOKUP($A8,Korrelation!$D$4:$D$1197,Korrelation!K$4:K$1197,"",0),'DM01-AV-CH'!$A$6:$A$834,0))) -> 0 | J8: {=IF(B8=0,IF(E8=0,"",HYPERLINK("#"&RIGHT(CELL("adresse",OFFSET(DMAV_Dienste!$M$6,E8-1,0)),LEN(CELL("adresse",OFFSET(DMAV_Dienste!$M$6,E8-1,0)))-FIND("]",CELL("adresse",OFFSET(DMAV_Dienste!$M$6,E8-1,0)))),"Dienst")),HYPERLINK("#"&RIGHT(CELL("adresse",OFFSET(DMAV_Modell!$N$6,B8-1,0)),LEN(CELL("adresse",OFFSET(DMAV_Modell!$N$6,B8-1,0)))-FIND("]",CELL("adresse",OFFSET(DMAV_Modell!$N$6,B8-1,0)))),"Modell"))} -> Modell | K8: {=IF($B8=0,IF($E8=0,"",IF(INDEX(DMAV_Dienste!P$6:P$140,$E8)="","",INDEX(DMAV_Dienste!P$6:P$140,$E8))),IF(INDEX(DMAV_Modell!Q$6:Q$838,$B8)="","",INDEX(DMAV_Modell!Q$6:Q$838,$B8)))} -> IMPORTS | L8: {=IF($B8=0,IF($E8=0,"",IF(INDEX(DMAV_Dienste!O$6:O$140,$E8)="","",INDEX(DMAV_Dienste!O$6:O$140,$E8))),IF(INDEX(DMAV_Modell!P$6:P$838,$B8)="","",INDEX(DMAV_Modell!P$6:P$838,$B8)))} | M8: {=IF($B8=0,IF($E8=0,"",IF(INDEX(DMAV_Dienste!Q$6:Q$140,$E8)="","",INDEX(DMAV_Dienste!Q$6:Q$140,$E8))),IF(INDEX(DMAV_Modell!R$6:R$838,$B8)="","",INDEX(DMAV_Modell!R$6:R$838,$B8)))} -> DMAV_Dienstbarkeitsgrenzen_V1_1 | N8: {=IF($B8=0,IF($E8=0,"",IF(INDEX(DMAV_Dienste!T$6:T$140,$E8)="","",INDEX(DMAV_Dienste!T$6:T$140,$E8))),IF(INDEX(DMAV_Modell!U$6:U$838,$B8)="","",INDEX(DMAV_Modell!U$6:U$838,$B8)))} | O8: {=IF(C8=0,IF(F8=0,"",HYPERLINK("#"&RIGHT(CELL("adresse",OFFSET(DMAV_Dienste!$M$6,F8-1,0)),LEN(CELL("adresse",OFFSET(DMAV_Dienste!$M$6,F8-1,0)))-FIND("]",CELL("adresse",OFFSET(DMAV_Dienste!$M$6,F8-1,0)))),"Structure")),HYPERLINK("#"&RIGHT(CELL("adresse",OFFSET(DMAV_Modell!$N$6,C8-1,0)),LEN(CELL("adresse",OFFSET(DMAV_Modell!$N$6,C8-1,0)))-FIND("]",CELL("adresse",OFFSET(DMAV_Modell!$N$6,C8-1,0)))),"Structure"))} | P8: {=IF(D8=0,IF(G8=0,"",HYPERLINK("#"&RIGHT(CELL("adresse",OFFSET(DMAV_Dienste!$M$6,G8-1,0)),LEN(CELL("adresse",OFFSET(DMAV_Dienste!$M$6,G8-1,0)))-FIND("]",CELL("adresse",OFFSET(DMAV_Dienste!$M$6,G8-1,0)))),"Substructure")),HYPERLINK("#"&RIGHT(CELL("adresse",OFFSET(DMAV_Modell!$N$6,D8-1,0)),LEN(CELL("adresse",OFFSET(DMAV_Modell!$N$6,D8-1,0)))-FIND("]",CELL("adresse",OFFSET(DMAV_Modell!$N$6,D8-1,0)))),"Substructure"))} | AF8: {=IF(H8=0,"",HYPERLINK("#"&RIGHT(CELL("adresse",OFFSET('DM01-AV-CH'!$G$6,H8-1,0)),LEN(CELL("adresse",OFFSET('DM01-AV-CH'!$G$6,H8-1,0)))-FIND("]",CELL("adresse",OFFSET('DM01-AV-CH'!$G$6,H8-1,0)))),"Modell"))} | AG8: {=IF($H8=0,"",IF(INDEX('DM01-AV-CH'!G$6:G$834,$H8)="","",INDEX('DM01-AV-CH'!G$6:G$834,$H8)))} | AH8: {=IF($H8=0,"",IF(INDEX('DM01-AV-CH'!H$6:H$834,$H8)="","",INDEX('DM01-AV-CH'!H$6:H$834,$H8)))} | AI8: {=IF($H8=0,"",IF(INDEX('DM01-AV-CH'!I$6:I$834,$H8)="","",INDEX('DM01-AV-CH'!I$6:I$834,$H8)))}
A9: 4 | B9: =IF($A9="","",IF(_xlfn.XLOOKUP($A9,Korrelation!$D$4:$D$1197,Korrelation!E$4:E$1197,"-",0)="-",0,MATCH(_xlfn.XLOOKUP($A9,Korrelation!$D$4:$D$1197,Korrelation!E$4:E$1197,"",0),DMAV_Modell!$G$6:$G$677,0))) -> 4 | C9: =IF($A9="","",IF(_xlfn.XLOOKUP($A9,Korrelation!$D$4:$D$1197,Korrelation!F$4:F$1197,"-",0)="-",0,MATCH(_xlfn.XLOOKUP($A9,Korrelation!$D$4:$D$1197,Korrelation!F$4:F$1197,"",0),DMAV_Modell!$G$6:$G$677,0))) -> 0 | D9: =IF($A9="","",IF(_xlfn.XLOOKUP($A9,Korrelation!$D$4:$D$1197,Korrelation!G$4:G$1197,"-",0)="-",0,MATCH(_xlfn.XLOOKUP($A9,Korrelation!$D$4:$D$1197,Korrelation!G$4:G$1197,"",0),DMAV_Modell!$G$6:$G$677,0))) -> 0 | E9: =IF($A9="","",IF(_xlfn.XLOOKUP($A9,Korrelation!$D$4:$D$1197,Korrelation!H$4:H$1197,"-",0)="-",0,MATCH(_xlfn.XLOOKUP($A9,Korrelation!$D$4:$D$1197,Korrelation!H$4:H$1197,"",0),DMAV_Dienste!$F$6:$F$140,0))) -> 0 | F9: =IF($A9="","",IF(_xlfn.XLOOKUP($A9,Korrelation!$D$4:$D$1197,Korrelation!I$4:I$1197,"-",0)="-",0,MATCH(_xlfn.XLOOKUP($A9,Korrelation!$D$4:$D$1197,Korrelation!I$4:I$1197,"",0),DMAV_Dienste!$F$6:$F$140,0))) -> 0 | G9: =IF($A9="","",IF(_xlfn.XLOOKUP($A9,Korrelation!$D$4:$D$1197,Korrelation!J$4:J$1197,"-",0)="-",0,MATCH(_xlfn.XLOOKUP($A9,Korrelation!$D$4:$D$1197,Korrelation!J$4:J$1197,"",0),DMAV_Dienste!$F$6:$F$140,0))) -> 0 | H9: =IF($A9="","",IF(_xlfn.XLOOKUP($A9,Korrelation!$D$4:$D$1197,Korrelation!K$4:K$1197,"-",0)="-",0,MATCH(_xlfn.XLOOKUP($A9,Korrelation!$D$4:$D$1197,Korrelation!K$4:K$1197,"",0),'DM01-AV-CH'!$A$6:$A$834,0))) -> 0 | J9: {=IF(B9=0,IF(E9=0,"",HYPERLINK("#"&RIGHT(CELL("adresse",OFFSET(DMAV_Dienste!$M$6,E9-1,0)),LEN(CELL("adresse",OFFSET(DMAV_Dienste!$M$6,E9-1,0)))-FIND("]",CELL("adresse",OFFSET(DMAV_Dienste!$M$6,E9-1,0)))),"Dienst")),HYPERLINK("#"&RIGHT(CELL("adresse",OFFSET(DMAV_Modell!$N$6,B9-1,0)),LEN(CELL("adresse",OFFSET(DMAV_Modell!$N$6,B9-1,0)))-FIND("]",CELL("adresse",OFFSET(DMAV_Modell!$N$6,B9-1,0)))),"Modell"))} -> Modell | K9: {=IF($B9=0,IF($E9=0,"",IF(INDEX(DMAV_Dienste!P$6:P$140,$E9)="","",INDEX(DMAV_Dienste!P$6:P$140,$E9))),IF(INDEX(DMAV_Modell!Q$6:Q$838,$B9)="","",INDEX(DMAV_Modell!Q$6:Q$838,$B9)))} -> IMPORTS | L9: {=IF($B9=0,IF($E9=0,"",IF(INDEX(DMAV_Dienste!O$6:O$140,$E9)="","",INDEX(DMAV_Dienste!O$6:O$140,$E9))),IF(INDEX(DMAV_Modell!P$6:P$838,$B9)="","",INDEX(DMAV_Modell!P$6:P$838,$B9)))} | M9: {=IF($B9=0,IF($E9=0,"",IF(INDEX(DMAV_Dienste!Q$6:Q$140,$E9)="","",INDEX(DMAV_Dienste!Q$6:Q$140,$E9))),IF(INDEX(DMAV_Modell!R$6:R$838,$B9)="","",INDEX(DMAV_Modell!R$6:R$838,$B9)))} -> DMAV_Einzelobjekte_V1_1 | N9: {=IF($B9=0,IF($E9=0,"",IF(INDEX(DMAV_Dienste!T$6:T$140,$E9)="","",INDEX(DMAV_Dienste!T$6:T$140,$E9))),IF(INDEX(DMAV_Modell!U$6:U$838,$B9)="","",INDEX(DMAV_Modell!U$6:U$838,$B9)))} | O9: {=IF(C9=0,IF(F9=0,"",HYPERLINK("#"&RIGHT(CELL("adresse",OFFSET(DMAV_Dienste!$M$6,F9-1,0)),LEN(CELL("adresse",OFFSET(DMAV_Dienste!$M$6,F9-1,0)))-FIND("]",CELL("adresse",OFFSET(DMAV_Dienste!$M$6,F9-1,0)))),"Structure")),HYPERLINK("#"&RIGHT(CELL("adresse",OFFSET(DMAV_Modell!$N$6,C9-1,0)),LEN(CELL("adresse",OFFSET(DMAV_Modell!$N$6,C9-1,0)))-FIND("]",CELL("adresse",OFFSET(DMAV_Modell!$N$6,C9-1,0)))),"Structure"))} | P9: {=IF(D9=0,IF(G9=0,"",HYPERLINK("#"&RIGHT(CELL("adresse",OFFSET(DMAV_Dienste!$M$6,G9-1,0)),LEN(CELL("adresse",OFFSET(DMAV_Dienste!$M$6,G9-1,0)))-FIND("]",CELL("adresse",OFFSET(DMAV_Dienste!$M$6,G9-1,0)))),"Substructure")),HYPERLINK("#"&RIGHT(CELL("adresse",OFFSET(DMAV_Modell!$N$6,D9-1,0)),LEN(CELL("adresse",OFFSET(DMAV_Modell!$N$6,D9-1,0)))-FIND("]",CELL("adresse",OFFSET(DMAV_Modell!$N$6,D9-1,0)))),"Substructure"))} | AF9: {=IF(H9=0,"",HYPERLINK("#"&RIGHT(CELL("adresse",OFFSET('DM01-AV-CH'!$G$6,H9-1,0)),LEN(CELL("adresse",OFFSET('DM01-AV-CH'!$G$6,H9-1,0)))-FIND("]",CELL("adresse",OFFSET('DM01-AV-CH'!$G$6,H9-1,0)))),"Modell"))} | AG9: {=IF($H9=0,"",IF(INDEX('DM01-AV-CH'!G$6:G$834,$H9)="","",INDEX('DM01-AV-CH'!G$6:G$834,$H9)))} | AH9: {=IF($H9=0,"",IF(INDEX('DM01-AV-CH'!H$6:H$834,$H9)="","",INDEX('DM01-AV-CH'!H$6:H$834,$H9)))} | AI9: {=IF($H9=0,"",IF(INDEX('DM01-AV-CH'!I$6:I$834,$H9)="","",INDEX('DM01-AV-CH'!I$6:I$834,$H9)))}
A10: 5 | B10: =IF($A10="","",IF(_xlfn.XLOOKUP($A10,Korrelation!$D$4:$D$1197,Korrelation!E$4:E$1197,"-",0)="-",0,MATCH(_xlfn.XLOOKUP($A10,Korrelation!$D$4:$D$1197,Korrelation!E$4:E$1197,"",0),DMAV_Modell!$G$6:$G$677,0))) -> 5 | C10: =IF($A10="","",IF(_xlfn.XLOOKUP($A10,Korrelation!$D$4:$D$1197,Korrelation!F$4:F$1197,"-",0)="-",0,MATCH(_xlfn.XLOOKUP($A10,Korrelation!$D$4:$D$1197,Korrelation!F$4:F$1197,"",0),DMAV_Modell!$G$6:$G$677,0))) -> 0 | D10: =IF($A10="","",IF(_xlfn.XLOOKUP($A10,Korrelation!$D$4:$D$1197,Korrelation!G$4:G$1197,"-",0)="-",0,MATCH(_xlfn.XLOOKUP($A10,Korrelation!$D$4:$D$1197,Korrelation!G$4:G$1197,"",0),DMAV_Modell!$G$6:$G$677,0))) -> 0 | E10: =IF($A10="","",IF(_xlfn.XLOOKUP($A10,Korrelation!$D$4:$D$1197,Korrelation!H$4:H$1197,"-",0)="-",0,MATCH(_xlfn.XLOOKUP($A10,Korrelation!$D$4:$D$1197,Korrelation!H$4:H$1197,"",0),DMAV_Dienste!$F$6:$F$140,0))) -> 0 | F10: =IF($A10="","",IF(_xlfn.XLOOKUP($A10,Korrelation!$D$4:$D$1197,Korrelation!I$4:I$1197,"-",0)="-",0,MATCH(_xlfn.XLOOKUP($A10,Korrelation!$D$4:$D$1197,Korrelation!I$4:I$1197,"",0),DMAV_Dienste!$F$6:$F$140,0))) -> 0 | G10: =IF($A10="","",IF(_xlfn.XLOOKUP($A10,Korrelation!$D$4:$D$1197,Korrelation!J$4:J$1197,"-",0)="-",0,MATCH(_xlfn.XLOOKUP($A10,Korrelation!$D$4:$D$1197,Korrelation!J$4:J$1197,"",0),DMAV_Dienste!$F$6:$F$140,0))) -> 0 | H10: =IF($A10="","",IF(_xlfn.XLOOKUP($A10,Korrelation!$D$4:$D$1197,Korrelation!K$4:K$1197,"-",0)="-",0,MATCH(_xlfn.XLOOKUP($A10,Korrelation!$D$4:$D$1197,Korrelation!K$4:K$1197,"",0),'DM01-AV-CH'!$A$6:$A$834,0))) -> 0 | J10: {=IF(B10=0,IF(E10=0,"",HYPERLINK("#"&RIGHT(CELL("adresse",OFFSET(DMAV_Dienste!$M$6,E10-1,0)),LEN(CELL("adresse",OFFSET(DMAV_Dienste!$M$6,E10-1,0)))-FIND("]",CELL("adresse",OFFSET(DMAV_Dienste!$M$6,E10-1,0)))),"Dienst")),HYPERLINK("#"&RIGHT(CELL("adresse",OFFSET(DMAV_Modell!$N$6,B10-1,0)),LEN(CELL("adresse",OFFSET(DMAV_Modell!$N$6,B10-1,0)))-FIND("]",CELL("adresse",OFFSET(DMAV_Modell!$N$6,B10-1,0)))),"Modell"))} -> Modell | K10: {=IF($B10=0,IF($E10=0,"",IF(INDEX(DMAV_Dienste!P$6:P$140,$E10)="","",INDEX(DMAV_Dienste!P$6:P$140,$E10))),IF(INDEX(DMAV_Modell!Q$6:Q$838,$B10)="","",INDEX(DMAV_Modell!Q$6:Q$838,$B10)))} -> IMPORTS | L10: {=IF($B10=0,IF($E10=0,"",IF(INDEX(DMAV_Dienste!O$6:O$140,$E10)="","",INDEX(DMAV_Dienste!O$6:O$140,$E10))),IF(INDEX(DMAV_Modell!P$6:P$838,$B10)="","",INDEX(DMAV_Modell!P$6:P$838,$B10)))} | M10: {=IF($B10=0,IF($E10=0,"",IF(INDEX(DMAV_Dienste!Q$6:Q$140,$E10)="","",INDEX(DMAV_Dienste!Q$6:Q$140,$E10))),IF(INDEX(DMAV_Modell!R$6:R$838,$B10)="","",INDEX(DMAV_Modell!R$6:R$838,$B10)))} -> DMAV_FixpunkteAVKategorie3_V1_1 | N10: {=IF($B10=0,IF($E10=0,"",IF(INDEX(DMAV_Dienste!T$6:T$140,$E10)="","",INDEX(DMAV_Dienste!T$6:T$140,$E10))),IF(INDEX(DMAV_Modell!U$6:U$838,$B10)="","",INDEX(DMAV_Modell!U$6:U$838,$B10)))} | O10: {=IF(C10=0,IF(F10=0,"",HYPERLINK("#"&RIGHT(CELL("adresse",OFFSET(DMAV_Dienste!$M$6,F10-1,0)),LEN(CELL("adresse",OFFSET(DMAV_Dienste!$M$6,F10-1,0)))-FIND("]",CELL("adresse",OFFSET(DMAV_Dienste!$M$6,F10-1,0)))),"Structure")),HYPERLINK("#"&RIGHT(CELL("adresse",OFFSET(DMAV_Modell!$N$6,C10-1,0)),LEN(CELL("adresse",OFFSET(DMAV_Modell!$N$6,C10-1,0)))-FIND("]",CELL("adresse",OFFSET(DMAV_Modell!$N$6,C10-1,0)))),"Structure"))} | P10: {=IF(D10=0,IF(G10=0,"",HYPERLINK("#"&RIGHT(CELL("adresse",OFFSET(DMAV_Dienste!$M$6,G10-1,0)),LEN(CELL("adresse",OFFSET(DMAV_Dienste!$M$6,G10-1,0)))-FIND("]",CELL("adresse",OFFSET(DMAV_Dienste!$M$6,G10-1,0)))),"Substructure")),HYPERLINK("#"&RIGHT(CELL("adresse",OFFSET(DMAV_Modell!$N$6,D10-1,0)),LEN(CELL("adresse",OFFSET(DMAV_Modell!$N$6,D10-1,0)))-FIND("]",CELL("adresse",OFFSET(DMAV_Modell!$N$6,D10-1,0)))),"Substructure"))} | AF10: {=IF(H10=0,"",HYPERLINK("#"&RIGHT(CELL("adresse",OFFSET('DM01-AV-CH'!$G$6,H10-1,0)),LEN(CELL("adresse",OFFSET('DM01-AV-CH'!$G$6,H10-1,0)))-FIND("]",CELL("adresse",OFFSET('DM01-AV-CH'!$G$6,H10-1,0)))),"Modell"))} | AG10: {=IF($H10=0,"",IF(INDEX('DM01-AV-CH'!G$6:G$834,$H10)="","",INDEX('DM01-AV-CH'!G$6:G$834,$H10)))} | AH10: {=IF($H10=0,"",IF(INDEX('DM01-AV-CH'!H$6:H$834,$H10)="","",INDEX('DM01-AV-CH'!H$6:H$834,$H10)))} | AI10: {=IF($H10=0,"",IF(INDEX('DM01-AV-CH'!I$6:I$834,$H10)="","",INDEX('DM01-AV-CH'!I$6:I$834,$H10)))}
A11: 6 | B11: =IF($A11="","",IF(_xlfn.XLOOKUP($A11,Korrelation!$D$4:$D$1197,Korrelation!E$4:E$1197,"-",0)="-",0,MATCH(_xlfn.XLOOKUP($A11,Korrelation!$D$4:$D$1197,Korrelation!E$4:E$1197,"",0),DMAV_Modell!$G$6:$G$677,0))) -> 6 | C11: =IF($A11="","",IF(_xlfn.XLOOKUP($A11,Korrelation!$D$4:$D$1197,Korrelation!F$4:F$1197,"-",0)="-",0,MATCH(_xlfn.XLOOKUP($A11,Korrelation!$D$4:$D$1197,Korrelation!F$4:F$1197,"",0),DMAV_Modell!$G$6:$G$677,0))) -> 0 | D11: =IF($A11="","",IF(_xlfn.XLOOKUP($A11,Korrelation!$D$4:$D$1197,Korrelation!G$4:G$1197,"-",0)="-",0,MATCH(_xlfn.XLOOKUP($A11,Korrelation!$D$4:$D$1197,Korrelation!G$4:G$1197,"",0),DMAV_Modell!$G$6:$G$677,0))) -> 0 | E11: =IF($A11="","",IF(_xlfn.XLOOKUP($A11,Korrelation!$D$4:$D$1197,Korrelation!H$4:H$1197,"-",0)="-",0,MATCH(_xlfn.XLOOKUP($A11,Korrelation!$D$4:$D$1197,Korrelation!H$4:H$1197,"",0),DMAV_Dienste!$F$6:$F$140,0))) -> 0 | F11: =IF($A11="","",IF(_xlfn.XLOOKUP($A11,Korrelation!$D$4:$D$1197,Korrelation!I$4:I$1197,"-",0)="-",0,MATCH(_xlfn.XLOOKUP($A11,Korrelation!$D$4:$D$1197,Korrelation!I$4:I$1197,"",0),DMAV_Dienste!$F$6:$F$140,0))) -> 0 | G11: =IF($A11="","",IF(_xlfn.XLOOKUP($A11,Korrelation!$D$4:$D$1197,Korrelation!J$4:J$1197,"-",0)="-",0,MATCH(_xlfn.XLOOKUP($A11,Korrelation!$D$4:$D$1197,Korrelation!J$4:J$1197,"",0),DMAV_Dienste!$F$6:$F$140,0))) -> 0 | H11: =IF($A11="","",IF(_xlfn.XLOOKUP($A11,Korrelation!$D$4:$D$1197,Korrelation!K$4:K$1197,"-",0)="-",0,MATCH(_xlfn.XLOOKUP($A11,Korrelation!$D$4:$D$1197,Korrelation!K$4:K$1197,"",0),'DM01-AV-CH'!$A$6:$A$834,0))) -> 0 | J11: {=IF(B11=0,IF(E11=0,"",HYPERLINK("#"&RIGHT(CELL("adresse",OFFSET(DMAV_Dienste!$M$6,E11-1,0)),LEN(CELL("adresse",OFFSET(DMAV_Dienste!$M$6,E11-1,0)))-FIND("]",CELL("adresse",OFFSET(DMAV_Dienste!$M$6,E11-1,0)))),"Dienst")),HYPERLINK("#"&RIGHT(CELL("adresse",OFFSET(DMAV_Modell!$N$6,B11-1,0)),LEN(CELL("adresse",OFFSET(DMAV_Modell!$N$6,B11-1,0)))-FIND("]",CELL("adresse",OFFSET(DMAV_Modell!$N$6,B11-1,0)))),"Modell"))} -> Modell | K11: {=IF($B11=0,IF($E11=0,"",IF(INDEX(DMAV_Dienste!P$6:P$140,$E11)="","",INDEX(DMAV_Dienste!P$6:P$140,$E11))),IF(INDEX(DMAV_Modell!Q$6:Q$838,$B11)="","",INDEX(DMAV_Modell!Q$6:Q$838,$B11)))} -> IMPORTS | L11: {=IF($B11=0,IF($E11=0,"",IF(INDEX(DMAV_Dienste!O$6:O$140,$E11)="","",INDEX(DMAV_Dienste!O$6:O$140,$E11))),IF(INDEX(DMAV_Modell!P$6:P$838,$B11)="","",INDEX(DMAV_Modell!P$6:P$838,$B11)))} | M11: {=IF($B11=0,IF($E11=0,"",IF(INDEX(DMAV_Dienste!Q$6:Q$140,$E11)="","",INDEX(DMAV_Dienste!Q$6:Q$140,$E11))),IF(INDEX(DMAV_Modell!R$6:R$838,$B11)="","",INDEX(DMAV_Modell!R$6:R$838,$B11)))} -> DMAV_Gebaeudeadressen_V1_1 | N11: {=IF($B11=0,IF($E11=0,"",IF(INDEX(DMAV_Dienste!T$6:T$140,$E11)="","",INDEX(DMAV_Dienste!T$6:T$140,$E11))),IF(INDEX(DMAV_Modell!U$6:U$838,$B11)="","",INDEX(DMAV_Modell!U$6:U$838,$B11)))} | O11: {=IF(C11=0,IF(F11=0,"",HYPERLINK("#"&RIGHT(CELL("adresse",OFFSET(DMAV_Dienste!$M$6,F11-1,0)),LEN(CELL("adresse",OFFSET(DMAV_Dienste!$M$6,F11-1,0)))-FIND("]",CELL("adresse",OFFSET(DMAV_Dienste!$M$6,F11-1,0)))),"Structure")),HYPERLINK("#"&RIGHT(CELL("adresse",OFFSET(DMAV_Modell!$N$6,C11-1,0)),LEN(CELL("adresse",OFFSET(DMAV_Modell!$N$6,C11-1,0)))-FIND("]",CELL("adresse",OFFSET(DMAV_Modell!$N$6,C11-1,0)))),"Structure"))} | P11: {=IF(D11=0,IF(G11=0,"",HYPERLINK("#"&RIGHT(CELL("adresse",OFFSET(DMAV_Dienste!$M$6,G11-1,0)),LEN(CELL("adresse",OFFSET(DMAV_Dienste!$M$6,G11-1,0)))-FIND("]",CELL("adresse",OFFSET(DMAV_Dienste!$M$6,G11-1,0)))),"Substructure")),HYPERLINK("#"&RIGHT(CELL("adresse",OFFSET(DMAV_Modell!$N$6,D11-1,0)),LEN(CELL("adresse",OFFSET(DMAV_Modell!$N$6,D11-1,0)))-FIND("]",CELL("adresse",OFFSET(DMAV_Modell!$N$6,D11-1,0)))),"Substructure"))} | AF11: {=IF(H11=0,"",HYPERLINK("#"&RIGHT(CELL("adresse",OFFSET('DM01-AV-CH'!$G$6,H11-1,0)),LEN(CELL("adresse",OFFSET('DM01-AV-CH'!$G$6,H11-1,0)))-FIND("]",CELL("adresse",OFFSET('DM01-AV-CH'!$G$6,H11-1,0)))),"Modell"))} | AG11: {=IF($H11=0,"",IF(INDEX('DM01-AV-CH'!G$6:G$834,$H11)="","",INDEX('DM01-AV-CH'!G$6:G$834,$H11)))} | AH11: {=IF($H11=0,"",IF(INDEX('DM01-AV-CH'!H$6:H$834,$H11)="","",INDEX('DM01-AV-CH'!H$6:H$834,$H11)))} | AI11: {=IF($H11=0,"",IF(INDEX('DM01-AV-CH'!I$6:I$834,$H11)="","",INDEX('DM01-AV-CH'!I$6:I$834,$H11)))}
A12: 7 | B12: =IF($A12="","",IF(_xlfn.XLOOKUP($A12,Korrelation!$D$4:$D$1197,Korrelation!E$4:E$1197,"-",0)="-",0,MATCH(_xlfn.XLOOKUP($A12,Korrelation!$D$4:$D$1197,Korrelation!E$4:E$1197,"",0),DMAV_Modell!$G$6:$G$677,0))) -> 7 | C12: =IF($A12="","",IF(_xlfn.XLOOKUP($A12,Korrelation!$D$4:$D$1197,Korrelation!F$4:F$1197,"-",0)="-",0,MATCH(_xlfn.XLOOKUP($A12,Korrelation!$D$4:$D$1197,Korrelation!F$4:F$1197,"",0),DMAV_Modell!$G$6:$G$677,0))) -> 0 | D12: =IF($A12="","",IF(_xlfn.XLOOKUP($A12,Korrelation!$D$4:$D$1197,Korrelation!G$4:G$1197,"-",0)="-",0,MATCH(_xlfn.XLOOKUP($A12,Korrelation!$D$4:$D$1197,Korrelation!G$4:G$1197,"",0),DMAV_Modell!$G$6:$G$677,0))) -> 0 | E12: =IF($A12="","",IF(_xlfn.XLOOKUP($A12,Korrelation!$D$4:$D$1197,Korrelation!H$4:H$1197,"-",0)="-",0,MATCH(_xlfn.XLOOKUP($A12,Korrelation!$D$4:$D$1197,Korrelation!H$4:H$1197,"",0),DMAV_Dienste!$F$6:$F$140,0))) -> 0 | F12: =IF($A12="","",IF(_xlfn.XLOOKUP($A12,Korrelation!$D$4:$D$1197,Korrelation!I$4:I$1197,"-",0)="-",0,MATCH(_xlfn.XLOOKUP($A12,Korrelation!$D$4:$D$1197,Korrelation!I$4:I$1197,"",0),DMAV_Dienste!$F$6:$F$140,0))) -> 0 | G12: =IF($A12="","",IF(_xlfn.XLOOKUP($A12,Korrelation!$D$4:$D$1197,Korrelation!J$4:J$1197,"-",0)="-",0,MATCH(_xlfn.XLOOKUP($A12,Korrelation!$D$4:$D$1197,Korrelation!J$4:J$1197,"",0),DMAV_Dienste!$F$6:$F$140,0))) -> 0 | H12: =IF($A12="","",IF(_xlfn.XLOOKUP($A12,Korrelation!$D$4:$D$1197,Korrelation!K$4:K$1197,"-",0)="-",0,MATCH(_xlfn.XLOOKUP($A12,Korrelation!$D$4:$D$1197,Korrelation!K$4:K$1197,"",0),'DM01-AV-CH'!$A$6:$A$834,0))) -> 0 | J12: {=IF(B12=0,IF(E12=0,"",HYPERLINK("#"&RIGHT(CELL("adresse",OFFSET(DMAV_Dienste!$M$6,E12-1,0)),LEN(CELL("adresse",OFFSET(DMAV_Dienste!$M$6,E12-1,0)))-FIND("]",CELL("adresse",OFFSET(DMAV_Dienste!$M$6,E12-1,0)))),"Dienst")),HYPERLINK("#"&RIGHT(CELL("adresse",OFFSET(DMAV_Modell!$N$6,B12-1,0)),LEN(CELL("adresse",OFFSET(DMAV_Modell!$N$6,B12-1,0)))-FIND("]",CELL("adresse",OFFSET(DMAV_Modell!$N$6,B12-1,0)))),"Modell"))} -> Modell | K12: {=IF($B12=0,IF($E12=0,"",IF(INDEX(DMAV_Dienste!P$6:P$140,$E12)="","",INDEX(DMAV_Dienste!P$6:P$140,$E12))),IF(INDEX(DMAV_Modell!Q$6:Q$838,$B12)="","",INDEX(DMAV_Modell!Q$6:Q$838,$B12)))} -> IMPORTS | L12: {=IF($B12=0,IF($E12=0,"",IF(INDEX(DMAV_Dienste!O$6:O$140,$E12)="","",INDEX(DMAV_Dienste!O$6:O$140,$E12))),IF(INDEX(DMAV_Modell!P$6:P$838,$B12)="","",INDEX(DMAV_Modell!P$6:P$838,$B12)))} | M12: {=IF($B12=0,IF($E12=0,"",IF(INDEX(DMAV_Dienste!Q$6:Q$140,$E12)="","",INDEX(DMAV_Dienste!Q$6:Q$140,$E12))),IF(INDEX(DMAV_Modell!R$6:R$838,$B12)="","",INDEX(DMAV_Modell!R$6:R$838,$B12)))} -> DMAV_Grundstuecke_V1_1 | N12: {=IF($B12=0,IF($E12=0,"",IF(INDEX(DMAV_Dienste!T$6:T$140,$E12)="","",INDEX(DMAV_Dienste!T$6:T$140,$E12))),IF(INDEX(DMAV_Modell!U$6:U$838,$B12)="","",INDEX(DMAV_Modell!U$6:U$838,$B12)))} | O12: {=IF(C12=0,IF(F12=0,"",HYPERLINK("#"&RIGHT(CELL("adresse",OFFSET(DMAV_Dienste!$M$6,F12-1,0)),LEN(CELL("adresse",OFFSET(DMAV_Dienste!$M$6,F12-1,0)))-FIND("]",CELL("adresse",OFFSET(DMAV_Dienste!$M$6,F12-1,0)))),"Structure")),HYPERLINK("#"&RIGHT(CELL("adresse",OFFSET(DMAV_Modell!$N$6,C12-1,0)),LEN(CELL("adresse",OFFSET(DMAV_Modell!$N$6,C12-1,0)))-FIND("]",CELL("adresse",OFFSET(DMAV_Modell!$N$6,C12-1,0)))),"Structure"))} | P12: {=IF(D12=0,IF(G12=0,"",HYPERLINK("#"&RIGHT(CELL("adresse",OFFSET(DMAV_Dienste!$M$6,G12-1,0)),LEN(CELL("adresse",OFFSET(DMAV_Dienste!$M$6,G12-1,0)))-FIND("]",CELL("adresse",OFFSET(DMAV_Dienste!$M$6,G12-1,0)))),"Substructure")),HYPERLINK("#"&RIGHT(CELL("adresse",OFFSET(DMAV_Modell!$N$6,D12-1,0)),LEN(CELL("adresse",OFFSET(DMAV_Modell!$N$6,D12-1,0)))-FIND("]",CELL("adresse",OFFSET(DMAV_Modell!$N$6,D12-1,0)))),"Substructure"))} | AF12: {=IF(H12=0,"",HYPERLINK("#"&RIGHT(CELL("adresse",OFFSET('DM01-AV-CH'!$G$6,H12-1,0)),LEN(CELL("adresse",OFFSET('DM01-AV-CH'!$G$6,H12-1,0)))-FIND("]",CELL("adresse",OFFSET('DM01-AV-CH'!$G$6,H12-1,0)))),"Modell"))} | AG12: {=IF($H12=0,"",IF(INDEX('DM01-AV-CH'!G$6:G$834,$H12)="","",INDEX('DM01-AV-CH'!G$6:G$834,$H12)))} | AH12: {=IF($H12=0,"",IF(INDEX('DM01-AV-CH'!H$6:H$834,$H12)="","",INDEX('DM01-AV-CH'!H$6:H$834,$H12)))} | AI12: {=IF($H12=0,"",IF(INDEX('DM01-AV-CH'!I$6:I$834,$H12)="","",INDEX('DM01-AV-CH'!I$6:I$834,$H12)))}
A13: 8 | B13: =IF($A13="","",IF(_xlfn.XLOOKUP($A13,Korrelation!$D$4:$D$1197,Korrelation!E$4:E$1197,"-",0)="-",0,MATCH(_xlfn.XLOOKUP($A13,Korrelation!$D$4:$D$1197,Korrelation!E$4:E$1197,"",0),DMAV_Modell!$G$6:$G$677,0))) -> 8 | C13: =IF($A13="","",IF(_xlfn.XLOOKUP($A13,Korrelation!$D$4:$D$1197,Korrelation!F$4:F$1197,"-",0)="-",0,MATCH(_xlfn.XLOOKUP($A13,Korrelation!$D$4:$D$1197,Korrelation!F$4:F$1197,"",0),DMAV_Modell!$G$6:$G$677,0))) -> 0 | D13: =IF($A13="","",IF(_xlfn.XLOOKUP($A13,Korrelation!$D$4:$D$1197,Korrelation!G$4:G$1197,"-",0)="-",0,MATCH(_xlfn.XLOOKUP($A13,Korrelation!$D$4:$D$1197,Korrelation!G$4:G$1197,"",0),DMAV_Modell!$G$6:$G$677,0))) -> 0 | E13: =IF($A13="","",IF(_xlfn.XLOOKUP($A13,Korrelation!$D$4:$D$1197,Korrelation!H$4:H$1197,"-",0)="-",0,MATCH(_xlfn.XLOOKUP($A13,Korrelation!$D$4:$D$1197,Korrelation!H$4:H$1197,"",0),DMAV_Dienste!$F$6:$F$140,0))) -> 0 | F13: =IF($A13="","",IF(_xlfn.XLOOKUP($A13,Korrelation!$D$4:$D$1197,Korrelation!I$4:I$1197,"-",0)="-",0,MATCH(_xlfn.XLOOKUP($A13,Korrelation!$D$4:$D$1197,Korrelation!I$4:I$1197,"",0),DMAV_Dienste!$F$6:$F$140,0))) -> 0 | G13: =IF($A13="","",IF(_xlfn.XLOOKUP($A13,Korrelation!$D$4:$D$1197,Korrelation!J$4:J$1197,"-",0)="-",0,MATCH(_xlfn.XLOOKUP($A13,Korrelation!$D$4:$D$1197,Korrelation!J$4:J$1197,"",0),DMAV_Dienste!$F$6:$F$140,0))) -> 0 | H13: =IF($A13="","",IF(_xlfn.XLOOKUP($A13,Korrelation!$D$4:$D$1197,Korrelation!K$4:K$1197,"-",0)="-",0,MATCH(_xlfn.XLOOKUP($A13,Korrelation!$D$4:$D$1197,Korrelation!K$4:K$1197,"",0),'DM01-AV-CH'!$A$6:$A$834,0))) -> 0 | J13: {=IF(B13=0,IF(E13=0,"",HYPERLINK("#"&RIGHT(CELL("adresse",OFFSET(DMAV_Dienste!$M$6,E13-1,0)),LEN(CELL("adresse",OFFSET(DMAV_Dienste!$M$6,E13-1,0)))-FIND("]",CELL("adresse",OFFSET(DMAV_Dienste!$M$6,E13-1,0)))),"Dienst")),HYPERLINK("#"&RIGHT(CELL("adresse",OFFSET(DMAV_Modell!$N$6,B13-1,0)),LEN(CELL("adresse",OFFSET(DMAV_Modell!$N$6,B13-1,0)))-FIND("]",CELL("adresse",OFFSET(DMAV_Modell!$N$6,B13-1,0)))),"Modell"))} -> Modell | K13: {=IF($B13=0,IF($E13=0,"",IF(INDEX(DMAV_Dienste!P$6:P$140,$E13)="","",INDEX(DMAV_Dienste!P$6:P$140,$E13))),IF(INDEX(DMAV_Modell!Q$6:Q$838,$B13)="","",INDEX(DMAV_Modell!Q$6:Q$838,$B13)))} -> IMPORTS | L13: {=IF($B13=0,IF($E13=0,"",IF(INDEX(DMAV_Dienste!O$6:O$140,$E13)="","",INDEX(DMAV_Dienste!O$6:O$140,$E13))),IF(INDEX(DMAV_Modell!P$6:P$838,$B13)="","",INDEX(DMAV_Modell!P$6:P$838,$B13)))} | M13: {=IF($B13=0,IF($E13=0,"",IF(INDEX(DMAV_Dienste!Q$6:Q$140,$E13)="","",INDEX(DMAV_Dienste!Q$6:Q$140,$E13))),IF(INDEX(DMAV_Modell!R$6:R$838,$B13)="","",INDEX(DMAV_Modell!R$6:R$838,$B13)))} -> DMAV_HoheitsgrenzenAV_V1_0 | N13: {=IF($B13=0,IF($E13=0,"",IF(INDEX(DMAV_Dienste!T$6:T$140,$E13)="","",INDEX(DMAV_Dienste!T$6:T$140,$E13))),IF(INDEX(DMAV_Modell!U$6:U$838,$B13)="","",INDEX(DMAV_Modell!U$6:U$838,$B13)))} | O13: {=IF(C13=0,IF(F13=0,"",HYPERLINK("#"&RIGHT(CELL("adresse",OFFSET(DMAV_Dienste!$M$6,F13-1,0)),LEN(CELL("adresse",OFFSET(DMAV_Dienste!$M$6,F13-1,0)))-FIND("]",CELL("adresse",OFFSET(DMAV_Dienste!$M$6,F13-1,0)))),"Structure")),HYPERLINK("#"&RIGHT(CELL("adresse",OFFSET(DMAV_Modell!$N$6,C13-1,0)),LEN(CELL("adresse",OFFSET(DMAV_Modell!$N$6,C13-1,0)))-FIND("]",CELL("adresse",OFFSET(DMAV_Modell!$N$6,C13-1,0)))),"Structure"))} | P13: {=IF(D13=0,IF(G13=0,"",HYPERLINK("#"&RIGHT(CELL("adresse",OFFSET(DMAV_Dienste!$M$6,G13-1,0)),LEN(CELL("adresse",OFFSET(DMAV_Dienste!$M$6,G13-1,0)))-FIND("]",CELL("adresse",OFFSET(DMAV_Dienste!$M$6,G13-1,0)))),"Substructure")),HYPERLINK("#"&RIGHT(CELL("adresse",OFFSET(DMAV_Modell!$N$6,D13-1,0)),LEN(CELL("adresse",OFFSET(DMAV_Modell!$N$6,D13-1,0)))-FIND("]",CELL("adresse",OFFSET(DMAV_Modell!$N$6,D13-1,0)))),"Substructure"))} | AF13: {=IF(H13=0,"",HYPERLINK("#"&RIGHT(CELL("adresse",OFFSET('DM01-AV-CH'!$G$6,H13-1,0)),LEN(CELL("adresse",OFFSET('DM01-AV-CH'!$G$6,H13-1,0)))-FIND("]",CELL("adresse",OFFSET('DM01-AV-CH'!$G$6,H13-1,0)))),"Modell"))} | AG13: {=IF($H13=0,"",IF(INDEX('DM01-AV-CH'!G$6:G$834,$H13)="","",INDEX('DM01-AV-CH'!G$6:G$834,$H13)))} | AH13: {=IF($H13=0,"",IF(INDEX('DM01-AV-CH'!H$6:H$834,$H13)="","",INDEX('DM01-AV-CH'!H$6:H$834,$H13)))} | AI13: {=IF($H13=0,"",IF(INDEX('DM01-AV-CH'!I$6:I$834,$H13)="","",INDEX('DM01-AV-CH'!I$6:I$834,$H13)))}
A14: 9 | B14: =IF($A14="","",IF(_xlfn.XLOOKUP($A14,Korrelation!$D$4:$D$1197,Korrelation!E$4:E$1197,"-",0)="-",0,MATCH(_xlfn.XLOOKUP($A14,Korrelation!$D$4:$D$1197,Korrelation!E$4:E$1197,"",0),DMAV_Modell!$G$6:$G$677,0))) -> 9 | C14: =IF($A14="","",IF(_xlfn.XLOOKUP($A14,Korrelation!$D$4:$D$1197,Korrelation!F$4:F$1197,"-",0)="-",0,MATCH(_xlfn.XLOOKUP($A14,Korrelation!$D$4:$D$1197,Korrelation!F$4:F$1197,"",0),DMAV_Modell!$G$6:$G$677,0))) -> 0 | D14: =IF($A14="","",IF(_xlfn.XLOOKUP($A14,Korrelation!$D$4:$D$1197,Korrelation!G$4:G$1197,"-",0)="-",0,MATCH(_xlfn.XLOOKUP($A14,Korrelation!$D$4:$D$1197,Korrelation!G$4:G$1197,"",0),DMAV_Modell!$G$6:$G$677,0))) -> 0 | E14: =IF($A14="","",IF(_xlfn.XLOOKUP($A14,Korrelation!$D$4:$D$1197,Korrelation!H$4:H$1197,"-",0)="-",0,MATCH(_xlfn.XLOOKUP($A14,Korrelation!$D$4:$D$1197,Korrelation!H$4:H$1197,"",0),DMAV_Dienste!$F$6:$F$140,0))) -> 0 | F14: =IF($A14="","",IF(_xlfn.XLOOKUP($A14,Korrelation!$D$4:$D$1197,Korrelation!I$4:I$1197,"-",0)="-",0,MATCH(_xlfn.XLOOKUP($A14,Korrelation!$D$4:$D$1197,Korrelation!I$4:I$1197,"",0),DMAV_Dienste!$F$6:$F$140,0))) -> 0 | G14: =IF($A14="","",IF(_xlfn.XLOOKUP($A14,Korrelation!$D$4:$D$1197,Korrelation!J$4:J$1197,"-",0)="-",0,MATCH(_xlfn.XLOOKUP($A14,Korrelation!$D$4:$D$1197,Korrelation!J$4:J$1197,"",0),DMAV_Dienste!$F$6:$F$140,0))) -> 0 | H14: =IF($A14="","",IF(_xlfn.XLOOKUP($A14,Korrelation!$D$4:$D$1197,Korrelation!K$4:K$1197,"-",0)="-",0,MATCH(_xlfn.XLOOKUP($A14,Korrelation!$D$4:$D$1197,Korrelation!K$4:K$1197,"",0),'DM01-AV-CH'!$A$6:$A$834,0))) -> 0 | J14: {=IF(B14=0,IF(E14=0,"",HYPERLINK("#"&RIGHT(CELL("adresse",OFFSET(DMAV_Dienste!$M$6,E14-1,0)),LEN(CELL("adresse",OFFSET(DMAV_Dienste!$M$6,E14-1,0)))-FIND("]",CELL("adresse",OFFSET(DMAV_Dienste!$M$6,E14-1,0)))),"Dienst")),HYPERLINK("#"&RIGHT(CELL("adresse",OFFSET(DMAV_Modell!$N$6,B14-1,0)),LEN(CELL("adresse",OFFSET(DMAV_Modell!$N$6,B14-1,0)))-FIND("]",CELL("adresse",OFFSET(DMAV_Modell!$N$6,B14-1,0)))),"Modell"))} -> Modell | K14: {=IF($B14=0,IF($E14=0,"",IF(INDEX(DMAV_Dienste!P$6:P$140,$E14)="","",INDEX(DMAV_Dienste!P$6:P$140,$E14))),IF(INDEX(DMAV_Modell!Q$6:Q$838,$B14)="","",INDEX(DMAV_Modell!Q$6:Q$838,$B14)))} -> IMPORTS | L14: {=IF($B14=0,IF($E14=0,"",IF(INDEX(DMAV_Dienste!O$6:O$140,$E14)="","",INDEX(DMAV_Dienste!O$6:O$140,$E14))),IF(INDEX(DMAV_Modell!P$6:P$838,$B14)="","",INDEX(DMAV_Modell!P$6:P$838,$B14)))} | M14: {=IF($B14=0,IF($E14=0,"",IF(INDEX(DMAV_Dienste!Q$6:Q$140,$E14)="","",INDEX(DMAV_Dienste!Q$6:Q$140,$E14))),IF(INDEX(DMAV_Modell!R$6:R$838,$B14)="","",INDEX(DMAV_Modell!R$6:R$838,$B14)))} -> DMAV_Nomenklatur_V1_1 | N14: {=IF($B14=0,IF($E14=0,"",IF(INDEX(DMAV_Dienste!T$6:T$140,$E14)="","",INDEX(DMAV_Dienste!T$6:T$140,$E14))),IF(INDEX(DMAV_Modell!U$6:U$838,$B14)="","",INDEX(DMAV_Modell!U$6:U$838,$B14)))} | O14: {=IF(C14=0,IF(F14=0,"",HYPERLINK("#"&RIGHT(CELL("adresse",OFFSET(DMAV_Dienste!$M$6,F14-1,0)),LEN(CELL("adresse",OFFSET(DMAV_Dienste!$M$6,F14-1,0)))-FIND("]",CELL("adresse",OFFSET(DMAV_Dienste!$M$6,F14-1,0)))),"Structure")),HYPERLINK("#"&RIGHT(CELL("adresse",OFFSET(DMAV_Modell!$N$6,C14-1,0)),LEN(CELL("adresse",OFFSET(DMAV_Modell!$N$6,C14-1,0)))-FIND("]",CELL("adresse",OFFSET(DMAV_Modell!$N$6,C14-1,0)))),"Structure"))} | P14: {=IF(D14=0,IF(G14=0,"",HYPERLINK("#"&RIGHT(CELL("adresse",OFFSET(DMAV_Dienste!$M$6,G14-1,0)),LEN(CELL("adresse",OFFSET(DMAV_Dienste!$M$6,G14-1,0)))-FIND("]",CELL("adresse",OFFSET(DMAV_Dienste!$M$6,G14-1,0)))),"Substructure")),HYPERLINK("#"&RIGHT(CELL("adresse",OFFSET(DMAV_Modell!$N$6,D14-1,0)),LEN(CELL("adresse",OFFSET(DMAV_Modell!$N$6,D14-1,0)))-FIND("]",CELL("adresse",OFFSET(DMAV_Modell!$N$6,D14-1,0)))),"Substructure"))} | AF14: {=IF(H14=0,"",HYPERLINK("#"&RIGHT(CELL("adresse",OFFSET('DM01-AV-CH'!$G$6,H14-1,0)),LEN(CELL("adresse",OFFSET('DM01-AV-CH'!$G$6,H14-1,0)))-FIND("]",CELL("adresse",OFFSET('DM01-AV-CH'!$G$6,H14-1,0)))),"Modell"))} | AG14: {=IF($H14=0,"",IF(INDEX('DM01-AV-CH'!G$6:G$834,$H14)="","",INDEX('DM01-AV-CH'!G$6:G$834,$H14)))} | AH14: {=IF($H14=0,"",IF(INDEX('DM01-AV-CH'!H$6:H$834,$H14)="","",INDEX('DM01-AV-CH'!H$6:H$834,$H14)))} | AI14: {=IF($H14=0,"",IF(INDEX('DM01-AV-CH'!I$6:I$834,$H14)="","",INDEX('DM01-AV-CH'!I$6:I$834,$H14)))}
A15: 10 | B15: =IF($A15="","",IF(_xlfn.XLOOKUP($A15,Korrelation!$D$4:$D$1197,Korrelation!E$4:E$1197,"-",0)="-",0,MATCH(_xlfn.XLOOKUP($A15,Korrelation!$D$4:$D$1197,Korrelation!E$4:E$1197,"",0),DMAV_Modell!$G$6:$G$677,0))) -> 10 | C15: =IF($A15="","",IF(_xlfn.XLOOKUP($A15,Korrelation!$D$4:$D$1197,Korrelation!F$4:F$1197,"-",0)="-",0,MATCH(_xlfn.XLOOKUP($A15,Korrelation!$D$4:$D$1197,Korrelation!F$4:F$1197,"",0),DMAV_Modell!$G$6:$G$677,0))) -> 0 | D15: =IF($A15="","",IF(_xlfn.XLOOKUP($A15,Korrelation!$D$4:$D$1197,Korrelation!G$4:G$1197,"-",0)="-",0,MATCH(_xlfn.XLOOKUP($A15,Korrelation!$D$4:$D$1197,Korrelation!G$4:G$1197,"",0),DMAV_Modell!$G$6:$G$677,0))) -> 0 | E15: =IF($A15="","",IF(_xlfn.XLOOKUP($A15,Korrelation!$D$4:$D$1197,Korrelation!H$4:H$1197,"-",0)="-",0,MATCH(_xlfn.XLOOKUP($A15,Korrelation!$D$4:$D$1197,Korrelation!H$4:H$1197,"",0),DMAV_Dienste!$F$6:$F$140,0))) -> 0 | F15: =IF($A15="","",IF(_xlfn.XLOOKUP($A15,Korrelation!$D$4:$D$1197,Korrelation!I$4:I$1197,"-",0)="-",0,MATCH(_xlfn.XLOOKUP($A15,Korrelation!$D$4:$D$1197,Korrelation!I$4:I$1197,"",0),DMAV_Dienste!$F$6:$F$140,0))) -> 0 | G15: =IF($A15="","",IF(_xlfn.XLOOKUP($A15,Korrelation!$D$4:$D$1197,Korrelation!J$4:J$1197,"-",0)="-",0,MATCH(_xlfn.XLOOKUP($A15,Korrelation!$D$4:$D$1197,Korrelation!J$4:J$1197,"",0),DMAV_Dienste!$F$6:$F$140,0))) -> 0 | H15: =IF($A15="","",IF(_xlfn.XLOOKUP($A15,Korrelation!$D$4:$D$1197,Korrelation!K$4:K$1197,"-",0)="-",0,MATCH(_xlfn.XLOOKUP($A15,Korrelation!$D$4:$D$1197,Korrelation!K$4:K$1197,"",0),'DM01-AV-CH'!$A$6:$A$834,0))) -> 0 | J15: {=IF(B15=0,IF(E15=0,"",HYPERLINK("#"&RIGHT(CELL("adresse",OFFSET(DMAV_Dienste!$M$6,E15-1,0)),LEN(CELL("adresse",OFFSET(DMAV_Dienste!$M$6,E15-1,0)))-FIND("]",CELL("adresse",OFFSET(DMAV_Dienste!$M$6,E15-1,0)))),"Dienst")),HYPERLINK("#"&RIGHT(CELL("adresse",OFFSET(DMAV_Modell!$N$6,B15-1,0)),LEN(CELL("adresse",OFFSET(DMAV_Modell!$N$6,B15-1,0)))-FIND("]",CELL("adresse",OFFSET(DMAV_Modell!$N$6,B15-1,0)))),"Modell"))} -> Modell | K15: {=IF($B15=0,IF($E15=0,"",IF(INDEX(DMAV_Dienste!P$6:P$140,$E15)="","",INDEX(DMAV_Dienste!P$6:P$140,$E15))),IF(INDEX(DMAV_Modell!Q$6:Q$838,$B15)="","",INDEX(DMAV_Modell!Q$6:Q$838,$B15)))} -> IMPORTS | L15: {=IF($B15=0,IF($E15=0,"",IF(INDEX(DMAV_Dienste!O$6:O$140,$E15)="","",INDEX(DMAV_Dienste!O$6:O$140,$E15))),IF(INDEX(DMAV_Modell!P$6:P$838,$B15)="","",INDEX(DMAV_Modell!P$6:P$838,$B15)))} | M15: {=IF($B15=0,IF($E15=0,"",IF(INDEX(DMAV_Dienste!Q$6:Q$140,$E15)="","",INDEX(DMAV_Dienste!Q$6:Q$140,$E15))),IF(INDEX(DMAV_Modell!R$6:R$838,$B15)="","",INDEX(DMAV_Modell!R$6:R$838,$B15)))} -> DMAV_Rohrleitungen_V1_1 | N15: {=IF($B15=0,IF($E15=0,"",IF(INDEX(DMAV_Dienste!T$6:T$140,$E15)="","",INDEX(DMAV_Dienste!T$6:T$140,$E15))),IF(INDEX(DMAV_Modell!U$6:U$838,$B15)="","",INDEX(DMAV_Modell!U$6:U$838,$B15)))} | O15: {=IF(C15=0,IF(F15=0,"",HYPERLINK("#"&RIGHT(CELL("adresse",OFFSET(DMAV_Dienste!$M$6,F15-1,0)),LEN(CELL("adresse",OFFSET(DMAV_Dienste!$M$6,F15-1,0)))-FIND("]",CELL("adresse",OFFSET(DMAV_Dienste!$M$6,F15-1,0)))),"Structure")),HYPERLINK("#"&RIGHT(CELL("adresse",OFFSET(DMAV_Modell!$N$6,C15-1,0)),LEN(CELL("adresse",OFFSET(DMAV_Modell!$N$6,C15-1,0)))-FIND("]",CELL("adresse",OFFSET(DMAV_Modell!$N$6,C15-1,0)))),"Structure"))} | P15: {=IF(D15=0,IF(G15=0,"",HYPERLINK("#"&RIGHT(CELL("adresse",OFFSET(DMAV_Dienste!$M$6,G15-1,0)),LEN(CELL("adresse",OFFSET(DMAV_Dienste!$M$6,G15-1,0)))-FIND("]",CELL("adresse",OFFSET(DMAV_Dienste!$M$6,G15-1,0)))),"Substructure")),HYPERLINK("#"&RIGHT(CELL("adresse",OFFSET(DMAV_Modell!$N$6,D15-1,0)),LEN(CELL("adresse",OFFSET(DMAV_Modell!$N$6,D15-1,0)))-FIND("]",CELL("adresse",OFFSET(DMAV_Modell!$N$6,D15-1,0)))),"Substructure"))} | AF15: {=IF(H15=0,"",HYPERLINK("#"&RIGHT(CELL("adresse",OFFSET('DM01-AV-CH'!$G$6,H15-1,0)),LEN(CELL("adresse",OFFSET('DM01-AV-CH'!$G$6,H15-1,0)))-FIND("]",CELL("adresse",OFFSET('DM01-AV-CH'!$G$6,H15-1,0)))),"Modell"))} | AG15: {=IF($H15=0,"",IF(INDEX('DM01-AV-CH'!G$6:G$834,$H15)="","",INDEX('DM01-AV-CH'!G$6:G$834,$H15)))} | AH15: {=IF($H15=0,"",IF(INDEX('DM01-AV-CH'!H$6:H$834,$H15)="","",INDEX('DM01-AV-CH'!H$6:H$834,$H15)))} | AI15: {=IF($H15=0,"",IF(INDEX('DM01-AV-CH'!I$6:I$834,$H15)="","",INDEX('DM01-AV-CH'!I$6:I$834,$H15)))}
A16: 11 | B16: =IF($A16="","",IF(_xlfn.XLOOKUP($A16,Korrelation!$D$4:$D$1197,Korrelation!E$4:E$1197,"-",0)="-",0,MATCH(_xlfn.XLOOKUP($A16,Korrelation!$D$4:$D$1197,Korrelation!E$4:E$1197,"",0),DMAV_Modell!$G$6:$G$677,0))) -> 11 | C16: =IF($A16="","",IF(_xlfn.XLOOKUP($A16,Korrelation!$D$4:$D$1197,Korrelation!F$4:F$1197,"-",0)="-",0,MATCH(_xlfn.XLOOKUP($A16,Korrelation!$D$4:$D$1197,Korrelation!F$4:F$1197,"",0),DMAV_Modell!$G$6:$G$677,0))) -> 0 | D16: =IF($A16="","",IF(_xlfn.XLOOKUP($A16,Korrelation!$D$4:$D$1197,Korrelation!G$4:G$1197,"-",0)="-",0,MATCH(_xlfn.XLOOKUP($A16,Korrelation!$D$4:$D$1197,Korrelation!G$4:G$1197,"",0),DMAV_Modell!$G$6:$G$677,0))) -> 0 | E16: =IF($A16="","",IF(_xlfn.XLOOKUP($A16,Korrelation!$D$4:$D$1197,Korrelation!H$4:H$1197,"-",0)="-",0,MATCH(_xlfn.XLOOKUP($A16,Korrelation!$D$4:$D$1197,Korrelation!H$4:H$1197,"",0),DMAV_Dienste!$F$6:$F$140,0))) -> 0 | F16: =IF($A16="","",IF(_xlfn.XLOOKUP($A16,Korrelation!$D$4:$D$1197,Korrelation!I$4:I$1197,"-",0)="-",0,MATCH(_xlfn.XLOOKUP($A16,Korrelation!$D$4:$D$1197,Korrelation!I$4:I$1197,"",0),DMAV_Dienste!$F$6:$F$140,0))) -> 0 | G16: =IF($A16="","",IF(_xlfn.XLOOKUP($A16,Korrelation!$D$4:$D$1197,Korrelation!J$4:J$1197,"-",0)="-",0,MATCH(_xlfn.XLOOKUP($A16,Korrelation!$D$4:$D$1197,Korrelation!J$4:J$1197,"",0),DMAV_Dienste!$F$6:$F$140,0))) -> 0 | H16: =IF($A16="","",IF(_xlfn.XLOOKUP($A16,Korrelation!$D$4:$D$1197,Korrelation!K$4:K$1197,"-",0)="-",0,MATCH(_xlfn.XLOOKUP($A16,Korrelation!$D$4:$D$1197,Korrelation!K$4:K$1197,"",0),'DM01-AV-CH'!$A$6:$A$834,0))) -> 0 | J16: {=IF(B16=0,IF(E16=0,"",HYPERLINK("#"&RIGHT(CELL("adresse",OFFSET(DMAV_Dienste!$M$6,E16-1,0)),LEN(CELL("adresse",OFFSET(DMAV_Dienste!$M$6,E16-1,0)))-FIND("]",CELL("adresse",OFFSET(DMAV_Dienste!$M$6,E16-1,0)))),"Dienst")),HYPERLINK("#"&RIGHT(CELL("adresse",OFFSET(DMAV_Modell!$N$6,B16-1,0)),LEN(CELL("adresse",OFFSET(DMAV_Modell!$N$6,B16-1,0)))-FIND("]",CELL("adresse",OFFSET(DMAV_Modell!$N$6,B16-1,0)))),"Modell"))} -> Modell | K16: {=IF($B16=0,IF($E16=0,"",IF(INDEX(DMAV_Dienste!P$6:P$140,$E16)="","",INDEX(DMAV_Dienste!P$6:P$140,$E16))),IF(INDEX(DMAV_Modell!Q$6:Q$838,$B16)="","",INDEX(DMAV_Modell!Q$6:Q$838,$B16)))} -> IMPORTS | L16: {=IF($B16=0,IF($E16=0,"",IF(INDEX(DMAV_Dienste!O$6:O$140,$E16)="","",INDEX(DMAV_Dienste!O$6:O$140,$E16))),IF(INDEX(DMAV_Modell!P$6:P$838,$B16)="","",INDEX(DMAV_Modell!P$6:P$838,$B16)))} | M16: {=IF($B16=0,IF($E16=0,"",IF(INDEX(DMAV_Dienste!Q$6:Q$140,$E16)="","",INDEX(DMAV_Dienste!Q$6:Q$140,$E16))),IF(INDEX(DMAV_Modell!R$6:R$838,$B16)="","",INDEX(DMAV_Modell!R$6:R$838,$B16)))} -> DMAV_Toleranzstufen_V1_1 | N16: {=IF($B16=0,IF($E16=0,"",IF(INDEX(DMAV_Dienste!T$6:T$140,$E16)="","",INDEX(DMAV_Dienste!T$6:T$140,$E16))),IF(INDEX(DMAV_Modell!U$6:U$838,$B16)="","",INDEX(DMAV_Modell!U$6:U$838,$B16)))} | O16: {=IF(C16=0,IF(F16=0,"",HYPERLINK("#"&RIGHT(CELL("adresse",OFFSET(DMAV_Dienste!$M$6,F16-1,0)),LEN(CELL("adresse",OFFSET(DMAV_Dienste!$M$6,F16-1,0)))-FIND("]",CELL("adresse",OFFSET(DMAV_Dienste!$M$6,F16-1,0)))),"Structure")),HYPERLINK("#"&RIGHT(CELL("adresse",OFFSET(DMAV_Modell!$N$6,C16-1,0)),LEN(CELL("adresse",OFFSET(DMAV_Modell!$N$6,C16-1,0)))-FIND("]",CELL("adresse",OFFSET(DMAV_Modell!$N$6,C16-1,0)))),"Structure"))} | P16: {=IF(D16=0,IF(G16=0,"",HYPERLINK("#"&RIGHT(CELL("adresse",OFFSET(DMAV_Dienste!$M$6,G16-1,0)),LEN(CELL("adresse",OFFSET(DMAV_Dienste!$M$6,G16-1,0)))-FIND("]",CELL("adresse",OFFSET(DMAV_Dienste!$M$6,G16-1,0)))),"Substructure")),HYPERLINK("#"&RIGHT(CELL("adresse",OFFSET(DMAV_Modell!$N$6,D16-1,0)),LEN(CELL("adresse",OFFSET(DMAV_Modell!$N$6,D16-1,0)))-FIND("]",CELL("adresse",OFFSET(DMAV_Modell!$N$6,D16-1,0)))),"Substructure"))} | AF16: {=IF(H16=0,"",HYPERLINK("#"&RIGHT(CELL("adresse",OFFSET('DM01-AV-CH'!$G$6,H16-1,0)),LEN(CELL("adresse",OFFSET('DM01-AV-CH'!$G$6,H16-1,0)))-FIND("]",CELL("adresse",OFFSET('DM01-AV-CH'!$G$6,H16-1,0)))),"Modell"))} | AG16: {=IF($H16=0,"",IF(INDEX('DM01-AV-CH'!G$6:G$834,$H16)="","",INDEX('DM01-AV-CH'!G$6:G$834,$H16)))} | AH16: {=IF($H16=0,"",IF(INDEX('DM01-AV-CH'!H$6:H$834,$H16)="","",INDEX('DM01-AV-CH'!H$6:H$834,$H16)))} | AI16: {=IF($H16=0,"",IF(INDEX('DM01-AV-CH'!I$6:I$834,$H16)="","",INDEX('DM01-AV-CH'!I$6:I$834,$H16)))}
